Workbook

Sheet Clients_Onboarding
A1: client_id | B1: company_name | C1: industry | D1: region | E1: company_size | F1: plan_type | G1: sales_rep | H1: csm_assigned | I1: contract_signed_date | J1: onboarding_start_date | K1: onboarding_complete_date | L1: days_to_onboard | M1: onboarding_status | N1: sla_met_14_days | O1: onboarding_csat | P1: contract_quarter | Q1: implementation_manager | R1: implementation_priority | S1: kickoff_date | T1: go_live_date | U1: delay_reason | V1: integration_required | W1: integration_type | X1: customer_segment | Y1: go_live_status | Z1: implementation_risk
A2: CB-1000 | B2: Vertex Solutions | C2: Manufacturing | D2: Chennai | E2: Small (1-50) | F2: Starter | G2: K. Joshi | H2: S. Reddy | I2: 46067 | J2: 46068 | K2: 46091 | L2: 23 | M2: Completed | N2: No | O2: 3 | P2: 2026-Q1 | Q2: Priya Nair | R2: Low | S2: 46068 | T2: 46091 | U2: Technical Issue | V2: Yes | W2: API | X2: Enterprise | Y2: Completed | Z2: Low
A3: CB-1001 | B3: Apex Group | C3: Retail & E-commerce | D3: Hyderabad | E3: Small (1-50) | F3: Starter | G3: A. Mehta | H3: J. Pillai | I3: 45876 | J3: 45878 | K3: 45900 | L3: 22 | M3: Completed | N3: No | O3: 4.1 | P3: 2025-Q3 | Q3: Priya Nair | R3: High | S3: 45878 | T3: 45900 | U3: Customer Delay | V3: No | W3: None | X3: Enterprise | Y3: Completed | Z3: Medium
A4: CB-1002 | B4: Harborlight Group | C4: Professional Services | D4: Ahmedabad | E4: Small (1-50) | F4: Enterprise | G4: S. Kapoor | H4: N. Verma | I4: 46109 | J4: 46110 | K4: 46151 | L4: 41 | M4: Completed | N4: No | O4: 4 | P4: 2026-Q1 | Q4: Karan Mehta | R4: High | S4: 46110 | T4: 46151 | U4: Technical Issue | V4: No | W4: None | X4: SMB | Y4: Completed | Z4: High
A5: CB-1003 | B5: Northbridge Industries | C5: Retail & E-commerce | D5: Mumbai | E5: Small (1-50) | F5: Growth | G5: S. Kapoor | H5: N. Verma | I5: 46028 | J5: 46031 | K5: 46057 | L5: 26 | M5: Completed | N5: No | O5: 2.8 | P5: 2026-Q1 | Q5: Priya Nair | R5: High | S5: 46031 | T5: 46057 | U5: Missing Documents | V5: Yes | W5: CRM | X5: Mid-Market | Y5: Completed | Z5: Low
A6: CB-1004 | B6: Driftwood Networks | C6: Real Estate | D6: Ahmedabad | E6: Large (251+) | F6: Enterprise | G6: P. Nair | H6: M. Khan | I6: 45562 | J6: 45564 | K6: 45585 | L6: 21 | M6: Completed | N6: No | O6: 3.9 | P6: 2024-Q3 | Q6: Priya Nair | R6: High | S6: 45564 | T6: 45585 | U6: Integration Delay | V6: No | W6: None | X6: Enterprise | Y6: Completed | Z6: Medium
A7: CB-1005 | B7: Granite Pvt Ltd | C7: FinTech | D7: Ahmedabad | E7: Mid (51-250) | F7: Growth | G7: K. Joshi | H7: M. Khan | I7: 46163 | J7: 46165 | K7: 46192 | L7: 27 | M7: Completed | N7: No | O7: 2.7 | P7: 2026-Q2 | Q7: Amit Singh | R7: Low | S7: 46165 | T7: 46192 | U7: Technical Issue | V7: Yes | W7: None | X7: Mid-Market | Y7: Completed | Z7: Medium
A8: CB-1006 | B8: Stratos Systems | C8: Logistics & Supply Chain | D8: Pune | E8: Small (1-50) | F8: Starter | G8: V. Shah | H8: T. D'Souza | I8: 46061 | J8: 46062 | K8: 46084 | L8: 22 | M8: Completed | N8: No | O8: 4.6 | P8: 2026-Q1 | Q8: Priya Nair | R8: High | S8: 46062 | T8: 46084 | U8: Resource Constraint | V8: Yes | W8: ERP | X8: Mid-Market | Y8: Completed | Z8: Low
A9: CB-1007 | B9: Highline Enterprises | C9: Hospitality | D9: Chennai | E9: Small (1-50) | F9: Starter | G9: S. Kapoor | H9: S. Reddy | I9: 46073 | J9: 46076 | K9: 46099 | L9: 23 | M9: Completed | N9: No | O9: 3.6 | P9: 2026-Q1 | Q9: Neha Patel | R9: Medium | S9: 46076 | T9: 46099 | U9: Scope Change | V9: No | W9: None | X9: Enterprise | Y9: Completed | Z9: Low
A10: CB-1008 | B10: Coral Enterprises | C10: Retail & E-commerce | D10: Bangalore | E10: Small (1-50) | F10: Growth | G10: P. Nair | H10: M. Khan | I10: 45607 | J10: 45610 | K10: 45626 | L10: 16 | M10: Completed | N10: No | O10: 5 | P10: 2024-Q4 | Q10: Neha Patel | R10: Low | S10: 45610 | T10: 45626 | U10: Missing Documents | V10: No | W10: None | X10: Mid-Market | Y10: Completed | Z10: High
A11: CB-1009 | B11: Meridian Group | C11: Retail & E-commerce | D11: Delhi NCR | E11: Large (251+) | F11: Starter | G11: K. Joshi | H11: N. Verma | I11: 45883 | J11: 45886 | K11: 45910 | L11: 24 | M11: Completed | N11: No | O11: 3.5 | P11: 2025-Q3 | Q11: Karan Mehta | R11: Low | S11: 45886 | T11: 45910 | U11: Customer Delay | V11: No | W11: None | X11: SMB | Y11: Completed | Z11: High
A12: CB-1010 | B12: Foxglove Ventures | C12: Retail & E-commerce | D12: Pune | E12: Small (1-50) | F12: Growth | G12: P. Nair | H12: M. Khan | I12: 45829 | J12: 45830 | K12: 45848 | L12: 18 | M12: Completed | N12: No | O12: 2.6 | P12: 2025-Q2 | Q12: Priya Nair | R12: High | S12: 45830 | T12: 45848 | U12: Resource Constraint | V12: Yes | W12: HRMS | X12: Mid-Market | Y12: Completed | Z12: Low
A13: CB-1011 | B13: Ironwood Enterprises | C13: FinTech | D13: Chennai | E13: Mid (51-250) | F13: Growth | G13: V. Shah | H13: T. D'Souza | I13: 46141 | J13: 46143 | K13: 46167 | L13: 24 | M13: Completed | N13: No | O13: 2.8 | P13: 2026-Q2 | Q13: Amit Singh | R13: Medium | S13: 46143 | T13: 46167 | U13: Technical Issue | V13: No | W13: None | X13: Enterprise | Y13: Completed | Z13: High
... A19: CB-1017 | B19: Brightline Enterprises | C19: Healthcare | D19: Chennai | E19: Large (251+) | F19: Starter | G19: K. Joshi | H19: N. Verma | I19: 45514 | J19: 45516 | K19: 45529 | L19: 13 | M19: Completed | N19: Yes | O19: 4.2 | P19: 2024-Q3 | Q19: Rahul Sharma | R19: Medium | S19: 45516 | T19: 45529 | U19: None | V19: Yes | W19: SSO | X19: SMB | Y19: Completed | Z19: Medium
A20: CB-1018 | B20: Driftwood Technologies | C20: Healthcare | D20: Pune | E20: Mid (51-250) | F20: Starter | G20: V. Shah | H20: N. Verma | I20: 46094 | J20: 46095 | M20: Dropped | P20: 2026-Q1 | Q20: Neha Patel | R20: Low | S20: 46095 | U20: Technical Issue | V20: Yes | W20: None | X20: Mid-Market | Y20: Dropped | Z20: Medium
A21: CB-1019 | B21: Trailmark Technologies | C21: Retail & E-commerce | D21: Pune | E21: Large (251+) | F21: Growth | G21: A. Mehta | H21: S. Reddy | I21: 45992 | J21: 45993 | M21: Dropped | P21: 2025-Q4 | Q21: Priya Nair | R21: Low | S21: 45993 | U21: Integration Delay | V21: Yes | W21: None | X21: Mid-Market | Y21: Dropped | Z21: Low
A22: CB-1020 | B22: Highline Networks | C22: Hospitality | D22: Ahmedabad | E22: Mid (51-250) | F22: Growth | G22: V. Shah | H22: S. Reddy | I22: 46059 | J22: 46060 | K22: 46085 | L22: 25 | M22: Completed | N22: No | O22: 4.6 | P22: 2026-Q1 | Q22: Rahul Sharma | R22: Low | S22: 46060 | T22: 46085 | U22: Scope Change | V22: No | W22: None | X22: Enterprise | Y22: Completed | Z22: Medium
A23: CB-1021 | B23: Brightline Group | C23: Logistics & Supply Chain | D23: Mumbai | E23: Mid (51-250) | F23: Starter | G23: K. Joshi | H23: N. Verma | I23: 45817 | J23: 45818 | K23: 45834 | L23: 16 | M23: Completed | N23: No | O23: 5 | P23: 2025-Q2 | Q23: Amit Singh | R23: Medium | S23: 45818 | T23: 45834 | U23: Customer Delay | V23: No | W23: None | X23: SMB | Y23: Completed | Z23: High
A24: CB-1022 | B24: Coral Enterprises | C24: FinTech | D24: Mumbai | E24: Small (1-50) | F24: Growth | G24: R. Iyer | H24: S. Reddy | I24: 46160 | J24: 46162 | K24: 46182 | L24: 20 | M24: Completed | N24: No | O24: 3.4 | P24: 2026-Q2 | Q24: Amit Singh | R24: High | S24: 46162 | T24: 46182 | U24: Integration Delay | V24: No | W24: None | X24: Enterprise | Y24: Completed | Z24: High
A25: CB-1023 | B25: Cobalt Pvt Ltd | C25: Hospitality | D25: Hyderabad | E25: Mid (51-250) | F25: Growth | G25: S. Kapoor | H25: S. Reddy | I25: 46125 | J25: 46127 | K25: 46155 | L25: 28 | M25: Completed | N25: No | O25: 3.5 | P25: 2026-Q2 | Q25: Karan Mehta | R25: Medium | S25: 46127 | T25: 46155 | U25: Technical Issue | V25: No | W25: None | X25: Enterprise | Y25: Completed | Z25: Medium
A26: CB-1024 | B26: Anchor Group | C26: FinTech | D26: Hyderabad | E26: Large (251+) | F26: Growth | G26: A. Mehta | H26: N. Verma | I26: 46070 | J26: 46073 | K26: 46097 | L26: 24 | M26: Completed | N26: No | O26: 5 | P26: 2026-Q1 | Q26: Karan Mehta | R26: Medium | S26: 46073 | T26: 46097 | U26: Technical Issue | V26: No | W26: None | X26: Mid-Market | Y26: Completed | Z26: High
A27: CB-1025 | B27: Anchor Ventures | C27: Manufacturing | D27: Ahmedabad | E27: Small (1-50) | F27: Starter | G27: R. Iyer | H27: M. Khan | I27: 45681 | J27: 45683 | K27: 45698 | L27: 15 | M27: Completed | N27: No | O27: 3.5 | P27: 2025-Q1 | Q27: Neha Patel | R27: Medium | S27: 45683 | T27: 45698 | U27: Resource Constraint | V27: No | W27: None | X27: Mid-Market | Y27: Completed | Z27: Low
A28: CB-1026 | B28: Driftwood Industries | C28: Hospitality | D28: Hyderabad | E28: Small (1-50) | F28: Starter | G28: R. Iyer | H28: J. Pillai | I28: 45894 | J28: 45895 | K28: 45920 | L28: 25 | M28: Completed | N28: No | O28: 4.1 | P28: 2025-Q3 | Q28: Karan Mehta | R28: Medium | S28: 45895 | T28: 45920 | U28: Integration Delay | V28: No | W28: None | X28: Enterprise | Y28: Completed | Z28: Low
A29: CB-1027 | B29: Lumen Group | C29: Professional Services | D29: Delhi NCR | E29: Mid (51-250) | F29: Growth | G29: P. Nair | H29: T. D'Souza | I29: 45476 | J29: 45479 | K29: 45498 | L29: 19 | M29: Completed | N29: No | O29: 4.1 | P29: 2024-Q3 | Q29: Priya Nair | R29: High | S29: 45479 | T29: 45498 | U29: Resource Constraint | V29: Yes | W29: CRM | X29: SMB | Y29: Completed | Z29: High
A30: CB-1028 | B30: Skyward Pvt Ltd | C30: Hospitality | D30: Delhi NCR | E30: Large (251+) | F30: Growth | G30: A. Mehta | H30: S. Reddy | I30: 45638 | J30: 45641 | K30: 45658 | L30: 17 | M30: Completed | N30: No | O30: 4.3 | P30: 2024-Q4 | Q30: Priya Nair | R30: High | S30: 45641 | T30: 45658 | U30: Technical Issue | V30: No | W30: None | X30: Mid-Market | Y30: Completed | Z30: Low
A31: CB-1029 | B31: Skyward Group | C31: Real Estate | D31: Bangalore | E31: Small (1-50) | F31: Starter | G31: S. Kapoor | H31: S. Reddy | I31: 46020 | J31: 46023 | K31: 46044 | L31: 21 | M31: Completed | N31: No | O31: 4.1 | P31: 2025-Q4 | Q31: Neha Patel | R31: High | S31: 46023 | T31: 46044 | U31: Technical Issue | V31: Yes | W31: HRMS | X31: Enterprise | Y31: Completed | Z31: High
A32: CB-1030 | B32: Crestline Solutions | C32: Professional Services | D32: Bangalore | E32: Small (1-50) | F32: Growth | G32: S. Kapoor | H32: S. Reddy | I32: 46053 | J32: 46055 | K32: 46075 | L32: 20 | M32: Completed | N32: No | O32: 3.4 | P32: 2026-Q1 | Q32: Priya Nair | R32: Medium | S32: 46055 | T32: 46075 | U32: Scope Change | V32: Yes | W32: CRM | X32: SMB | Y32: Completed | Z32: Low
A33: CB-1031 | B33: Quantix Enterprises | C33: Manufacturing | D33: Delhi NCR | E33: Large (251+) | F33: Enterprise | G33: S. Kapoor | H33: J. Pillai | I33: 46159 | J33: 46162 | K33: 46192 | L33: 30 | M33: Completed | N33: No | O33: 2.8 | P33: 2026-Q2 | Q33: Neha Patel | R33: Low | S33: 46162 | T33: 46192 | U33: Resource Constraint | V33: Yes | W33: CRM | X33: Enterprise | Y33: Completed | Z33: Low
... A42: CB-1040 | B42: Trailmark Ventures | C42: FinTech | D42: Chennai | E42: Large (251+) | F42: Enterprise | G42: S. Kapoor | H42: S. Reddy | I42: 45875 | J42: 45877 | K42: 45907 | L42: 30 | M42: Completed | N42: No | O42: 3.4 | P42: 2025-Q3 | Q42: Amit Singh | R42: High | S42: 45877 | T42: 45907 | U42: Integration Delay | V42: Yes | W42: SSO | X42: SMB | Y42: Completed | Z42: Low
A43: CB-1041 | B43: Westgate Ventures | C43: Logistics & Supply Chain | D43: Bangalore | E43: Mid (51-250) | F43: Enterprise | G43: K. Joshi | H43: S. Reddy | I43: 46096 | J43: 46099 | M43: Dropped | P43: 2026-Q1 | Q43: Priya Nair | R43: Medium | S43: 46099 | U43: Technical Issue | V43: No | W43: None | X43: Mid-Market | Y43: Dropped | Z43: Low
A44: CB-1042 | B44: Skyward Labs | C44: Hospitality | D44: Delhi NCR | E44: Large (251+) | F44: Enterprise | G44: R. Iyer | H44: S. Reddy | I44: 46030 | J44: 46031 | K44: 46064 | L44: 33 | M44: Completed | N44: No | O44: 3.4 | P44: 2026-Q1 | Q44: Neha Patel | R44: Medium | S44: 46031 | T44: 46064 | U44: Missing Documents | V44: Yes | W44: HRMS | X44: SMB | Y44: Completed | Z44: High
A45: CB-1043 | B45: Granite Group | C45: Real Estate | D45: Pune | E45: Small (1-50) | F45: Growth | G45: K. Joshi | H45: N. Verma | I45: 45784 | J45: 45786 | K45: 45808 | L45: 22 | M45: Completed | N45: No | O45: 4.1 | P45: 2025-Q2 | Q45: Amit Singh | R45: Medium | S45: 45786 | T45: 45808 | U45: Scope Change | V45: No | W45: None | X45: Enterprise | Y45: Completed | Z45: Medium
A46: CB-1044 | B46: Coral Labs | C46: Logistics & Supply Chain | D46: Chennai | E46: Large (251+) | F46: Enterprise | G46: S. Kapoor | H46: S. Reddy | I46: 46096 | J46: 46099 | K46: 46131 | L46: 32 | M46: Completed | N46: No | O46: 3.5 | P46: 2026-Q1 | Q46: Neha Patel | R46: Medium | S46: 46099 | T46: 46131 | U46: Integration Delay | V46: No | W46: None | X46: Mid-Market | Y46: Completed | Z46: High
A47: CB-1045 | B47: Northbridge Systems | C47: Retail & E-commerce | D47: Ahmedabad | E47: Small (1-50) | F47: Growth | G47: P. Nair | H47: M. Khan | I47: 46083 | J47: 46085 | K47: 46108 | L47: 23 | M47: Completed | N47: No | O47: 3.2 | P47: 2026-Q1 | Q47: Priya Nair | R47: High | S47: 46085 | T47: 46108 | U47: Resource Constraint | V47: No | W47: None | X47: Mid-Market | Y47: Completed | Z47: Medium
A48: CB-1046 | B48: Anchor Networks | C48: FinTech | D48: Bangalore | E48: Mid (51-250) | F48: Enterprise | G48: V. Shah | H48: J. Pillai | I48: 45841 | J48: 45842 | K48: 45869 | L48: 27 | M48: Completed | N48: No | O48: 3.2 | P48: 2025-Q3 | Q48: Priya Nair | R48: Low | S48: 45842 | T48: 45869 | U48: Customer Delay | V48: Yes | W48: ERP | X48: Mid-Market | Y48: Completed | Z48: High
A49: CB-1047 | B49: Apex Enterprises | C49: Retail & E-commerce | D49: Hyderabad | E49: Large (251+) | F49: Growth | G49: S. Kapoor | H49: J. Pillai | I49: 45765 | J49: 45768 | K49: 45789 | L49: 21 | M49: Completed | N49: No | O49: 3.9 | P49: 2025-Q2 | Q49: Rahul Sharma | R49: Medium | S49: 45768 | T49: 45789 | U49: Scope Change | V49: No | W49: None | X49: Mid-Market | Y49: Completed | Z49: High
A50: CB-1048 | B50: Brightline Group | C50: Manufacturing | D50: Ahmedabad | E50: Mid (51-250) | F50: Growth | G50: A. Mehta | H50: T. D'Souza | I50: 46020 | J50: 46021 | K50: 46043 | L50: 22 | M50: Completed | N50: No | O50: 4.9 | P50: 2025-Q4 | Q50: Rahul Sharma | R50: Medium | S50: 46021 | T50: 46043 | U50: Customer Delay | V50: Yes | W50: None | X50: SMB | Y50: Completed | Z50: Medium
A51: CB-1049 | B51: Crestline Technologies | C51: Retail & E-commerce | D51: Bangalore | E51: Small (1-50) | F51: Starter | G51: R. Iyer | H51: S. Reddy | I51: 45621 | J51: 45623 | K51: 45641 | L51: 18 | M51: Completed | N51: No | O51: 3 | P51: 2024-Q4 | Q51: Karan Mehta | R51: High | S51: 45623 | T51: 45641 | U51: Technical Issue | V51: Yes | W51: CRM | X51: SMB | Y51: Completed | Z51: High
A52: CB-1050 | B52: Cinder Labs | C52: FinTech | D52: Delhi NCR | E52: Large (251+) | F52: Starter | G52: S. Kapoor | H52: T. D'Souza | I52: 45686 | J52: 45689 | K52: 45699 | L52: 10 | M52: Completed | N52: Yes | O52: 2.5 | P52: 2025-Q1 | Q52: Amit Singh | R52: Low | S52: 45689 | T52: 45699 | U52: None | V52: No | W52: None | X52: SMB | Y52: Completed | Z52: Medium
A53: CB-1051 | B53: Foxglove Industries | C53: Logistics & Supply Chain | D53: Hyderabad | E53: Small (1-50) | F53: Starter | G53: P. Nair | H53: T. D'Souza | I53: 45367 | J53: 45368 | K53: 45378 | L53: 10 | M53: Completed | N53: Yes | O53: 4.4 | P53: 2024-Q1 | Q53: Karan Mehta | R53: Low | S53: 45368 | T53: 45378 | U53: None | V53: No | W53: None | X53: Enterprise | Y53: Completed | Z53: Low
...

Sheet Renewals_HealthScore
A1: client_id | B1: plan_type | C1: annual_recurring_revenue_inr | D1: renewal_date | E1: usage_score | F1: support_tickets_90d | G1: payment_delay_days | H1: health_score | I1: renewal_outcome | J1: churn_reason | K1: renewed_arr_inr | L1: renewal_quarter
A2: CB-1004 | B2: Enterprise | C2: 492892 | D2: 45927 | E2: 55.3 | F2: 5 | G2: 0 | H2: 46.4 | I2: Renewed | K2: 498024 | L2: 2025-Q3
A3: CB-1008 | B3: Growth | C3: 148960 | D3: 45972 | E3: 91.3 | F3: 1 | G3: 2 | H3: 72.2 | I3: Renewed | K3: 145812 | L3: 2025-Q4
A4: CB-1010 | B4: Growth | C4: 148520 | D4: 46194 | E4: 46.7 | F4: 2 | G4: 2 | H4: 45.9 | I4: Churned | J4: Price increase at renewal | L4: 2026-Q2
A5: CB-1015 | B5: Starter | C5: 68846 | D5: 46077 | E5: 78.3 | F5: 2 | G5: 10 | H5: 58.5 | I5: Churned | J5: Company downsized or shut down | L5: 2026-Q1
A6: CB-1017 | B6: Starter | C6: 53470 | D6: 45879 | E6: 65.6 | F6: 2 | G6: 5 | H6: 54.5 | I6: Renewed | K6: 52377 | L6: 2025-Q3
A7: CB-1021 | B7: Starter | C7: 55243 | D7: 46182 | E7: 46.4 | F7: 2 | G7: 1 | H7: 46.3 | I7: Renewed - Upsold | K7: 68064 | L7: 2026-Q2
A8: CB-1025 | B8: Starter | C8: 56975 | D8: 46046 | E8: 78.6 | F8: 6 | G8: 13 | H8: 49.7 | I8: Renewed | K8: 59633 | L8: 2026-Q1
A9: CB-1027 | B9: Growth | C9: 224639 | D9: 45841 | E9: 54.9 | F9: 2 | G9: 1 | H9: 51 | I9: Renewed | K9: 222389 | L9: 2025-Q3
A10: CB-1028 | B10: Growth | C10: 176044 | D10: 46003 | E10: 70.9 | F10: 3 | G10: 2 | H10: 57.4 | I10: Renewed | K10: 184143 | L10: 2025-Q4
A11: CB-1032 | B11: Starter | C11: 73151 | D11: 46160 | E11: 58.9 | F11: 1 | G11: 2 | H11: 54.4 | I11: Renewed - Upsold | K11: 92401 | L11: 2026-Q2
A12: CB-1033 | B12: Enterprise | C12: 562250 | D12: 46193 | E12: 77.3 | F12: 3 | G12: 0 | H12: 62.1 | I12: Renewed | K12: 570463 | L12: 2026-Q2
A13: CB-1035 | B13: Starter | C13: 80445 | D13: 46040 | E13: 69.5 | F13: 5 | G13: 1 | H13: 53.6 | I13: Renewed | K13: 79284 | L13: 2026-Q1
A14: CB-1036 | B14: Starter | C14: 61572 | D14: 45974 | E14: 69.9 | F14: 2 | G14: 2 | H14: 58.6 | I14: Renewed | K14: 62939 | L14: 2025-Q4
A15: CB-1038 | B15: Starter | C15: 56538 | D15: 46077 | E15: 84.5 | F15: 2 | G15: 6 | H15: 64.3 | I15: Churned | J15: Poor onboarding experience | L15: 2026-Q1
A16: CB-1043 | B16: Growth | C16: 125597 | D16: 46149 | E16: 71 | F16: 2 | G16: 8 | H16: 55.7 | I16: Renewed | K16: 130738 | L16: 2026-Q2
A17: CB-1047 | B17: Growth | C17: 191630 | D17: 46130 | E17: 57.7 | F17: 4 | G17: 10 | H17: 43.5 | I17: At Risk - Pending Decision | L17: 2026-Q2
A18: CB-1049 | B18: Starter | C18: 66911 | D18: 45986 | E18: 67.4 | F18: 5 | G18: 3 | H18: 51.2 | I18: Renewed | K18: 67562 | L18: 2025-Q4
A19: CB-1050 | B19: Starter | C19: 59061 | D19: 46051 | E19: 74.2 | F19: 4 | G19: 4 | H19: 56.2 | I19: Renewed | K19: 60005 | L19: 2026-Q1
A20: CB-1051 | B20: Starter | C20: 73369 | D20: 45732 | E20: 77.5 | F20: 7 | G20: 9 | H20: 49.6 | I20: Renewed | K20: 73483 | L20: 2025-Q1
A21: CB-1058 | B21: Starter | C21: 72733 | D21: 45986 | E21: 49 | F21: 1 | G21: 1 | H21: 49.6 | I21: Renewed | K21: 73411 | L21: 2025-Q4
A22: CB-1059 | B22: Starter | C22: 39946 | D22: 45955 | E22: 56.2 | F22: 3 | G22: 0 | H22: 50.5 | I22: Renewed | K22: 40608 | L22: 2025-Q4
A23: CB-1067 | B23: Growth | C23: 227505 | D23: 46143 | E23: 65.4 | F23: 6 | G23: 1 | H23: 49.6 | I23: Renewed | K23: 232900 | L23: 2026-Q2
A24: CB-1068 | B24: Starter | C24: 67174 | D24: 45811 | E24: 71.5 | F24: 6 | G24: 3 | H24: 51.7 | I24: Renewed | K24: 68860 | L24: 2025-Q2
A25: CB-1070 | B25: Growth | C25: 145741 | D25: 46065 | E25: 66.1 | F25: 6 | G25: 3 | H25: 48.7 | I25: Churned | J25: Poor onboarding experience | L25: 2026-Q1
A26: CB-1073 | B26: Starter | C26: 49110 | D26: 46083 | E26: 45.3 | F26: 4 | G26: 3 | H26: 40.9 | I26: Renewed | K26: 49249 | L26: 2026-Q1
A27: CB-1074 | B27: Growth | C27: 226526 | D27: 45869 | E27: 62.6 | F27: 4 | G27: 0 | H27: 52.2 | I27: Renewed | K27: 224660 | L27: 2025-Q3
A28: CB-1075 | B28: Growth | C28: 219945 | D28: 46124 | E28: 77.8 | F28: 3 | G28: 0 | H28: 62.4 | I28: At Risk - Pending Decision | L28: 2026-Q2
A29: CB-1076 | B29: Enterprise | C29: 360933 | D29: 46134 | E29: 58.9 | F29: 3 | G29: 1 | H29: 51.4 | I29: Renewed | K29: 374285 | L29: 2026-Q2
A30: CB-1083 | B30: Starter | C30: 62277 | D30: 46017 | E30: 57 | F30: 8 | G30: 6 | H30: 38.4 | I30: Renewed | K30: 63774 | L30: 2025-Q4
A31: CB-1084 | B31: Enterprise | C31: 556688 | D31: 45789 | E31: 76.8 | F31: 4 | G31: 2 | H31: 58.8 | I31: Renewed | K31: 551555 | L31: 2025-Q2
A32: CB-1085 | B32: Growth | C32: 185821 | D32: 45921 | E32: 70 | F32: 1 | G32: 2 | H32: 60.5 | I32: Renewed - Upsold | K32: 235147 | L32: 2025-Q3
A33: CB-1088 | B33: Starter | C33: 55007 | D33: 46011 | E33: 66.3 | F33: 3 | G33: 12 | H33: 48.8 | I33: Churned | J33: Lack of key feature (AI/automation) | L33: 2025-Q4
A34: CB-1090 | B34: Growth | C34: 213032 | D34: 46001 | E34: 63.9 | F34: 5 | G34: 4 | H34: 48.7 | I34: Renewed | K34: 219100 | L34: 2025-Q4
A35: CB-1093 | B35: Enterprise | C35: 561274 | D35: 46201 | E35: 78.1 | F35: 1 | G35: 0 | H35: 66.1 | I35: Renewed | K35: 571230 | L35: 2026-Q2
A36: CB-1094 | B36: Starter | C36: 54238 | D36: 46141 | E36: 56.3 | F36: 3 | G36: 8 | H36: 45.8 | I36: Churned | J36: Lack of key feature (AI/automation) | L36: 2026-Q2
A37: CB-1096 | B37: Enterprise | C37: 533787 | D37: 46187 | E37: 64.5 | F37: 5 | G37: 1 | H37: 50.9 | I37: Renewed | K37: 529324 | L37: 2026-Q2
A38: CB-1097 | B38: Starter | C38: 76249 | D38: 45918 | E38: 100 | F38: 0 | G38: 14 | H38: 71.6 | I38: Renewed | K38: 75239 | L38: 2025-Q3
A39: CB-1098 | B39: Enterprise | C39: 492907 | D39: 45959 | E39: 71.5 | F39: 1 | G39: 8 | H39: 57.7 | I39: Renewed | K39: 510259 | L39: 2025-Q4
A40: CB-1102 | B40: Starter | C40: 70474 | D40: 46111 | E40: 82 | F40: 7 | G40: 0 | H40: 57.5 | I40: Renewed | K40: 70674 | L40: 2026-Q1
...

Sheet Trend_Summary
A1: Quarter | B1: Avg Days to Onboard | C1: SLA Met % (<=14 days) | D1: Avg Onboarding CSAT | E1: Renewals Closed | F1: Renewed Count | G1: Renewal Rate % | H1: Churned Count | I1: Avg Health Score - Churned | J1: Avg Health Score - Renewed
A2: 2024-Q1 | B2: =IFERROR(ROUND(AVERAGEIFS(Clients_Onboarding!L:L,Clients_Onboarding!P:P,A2,Clients_Onboarding!M:M,"Completed"),1),"-") -> 10 | C2: =IFERROR(ROUND(COUNTIFS(Clients_Onboarding!P:P,A2,Clients_Onboarding!N:N,"Yes")/COUNTIFS(Clients_Onboarding!P:P,A2,Clients_Onboarding!M:M,"Completed"),3),"-") -> 1 | D2: =IFERROR(ROUND(AVERAGEIFS(Clients_Onboarding!O:O,Clients_Onboarding!P:P,A2),2),"-") -> 4.4 | E2: =COUNTIFS(Renewals_HealthScore!L:L,A2) -> 0 | F2: =COUNTIFS(Renewals_HealthScore!L:L,A2,Renewals_HealthScore!I:I,"Renewed")+COUNTIFS(Renewals_HealthScore!L:L,A2,Renewals_HealthScore!I:I,"Renewed - Upsold") -> 0 | G2: =IFERROR(ROUND(F2/E2,3),"-") -> - | H2: =COUNTIFS(Renewals_HealthScore!L:L,A2,Renewals_HealthScore!I:I,"Churned") -> 0 | I2: =IFERROR(ROUND(AVERAGEIFS(Renewals_HealthScore!H:H,Renewals_HealthScore!L:L,A2,Renewals_HealthScore!I:I,"Churned"),1),"-") -> - | J2: =IFERROR(ROUND(AVERAGEIFS(Renewals_HealthScore!H:H,Renewals_HealthScore!L:L,A2,Renewals_HealthScore!I:I,"Renewed"),1),"-") -> -
A3: 2024-Q2 | B3: =IFERROR(ROUND(AVERAGEIFS(Clients_Onboarding!L:L,Clients_Onboarding!P:P,A3,Clients_Onboarding!M:M,"Completed"),1),"-") -> 12.8 | C3: =IFERROR(ROUND(COUNTIFS(Clients_Onboarding!P:P,A3,Clients_Onboarding!N:N,"Yes")/COUNTIFS(Clients_Onboarding!P:P,A3,Clients_Onboarding!M:M,"Completed"),3),"-") -> 0.778 | D3: =IFERROR(ROUND(AVERAGEIFS(Clients_Onboarding!O:O,Clients_Onboarding!P:P,A3),2),"-") -> 3.92 | E3: =COUNTIFS(Renewals_HealthScore!L:L,A3) -> 0 | F3: =COUNTIFS(Renewals_HealthScore!L:L,A3,Renewals_HealthScore!I:I,"Renewed")+COUNTIFS(Renewals_HealthScore!L:L,A3,Renewals_HealthScore!I:I,"Renewed - Upsold") -> 0 | G3: =IFERROR(ROUND(F3/E3,3),"-") -> - | H3: =COUNTIFS(Renewals_HealthScore!L:L,A3,Renewals_HealthScore!I:I,"Churned") -> 0 | I3: =IFERROR(ROUND(AVERAGEIFS(Renewals_HealthScore!H:H,Renewals_HealthScore!L:L,A3,Renewals_HealthScore!I:I,"Churned"),1),"-") -> - | J3: =IFERROR(ROUND(AVERAGEIFS(Renewals_HealthScore!H:H,Renewals_HealthScore!L:L,A3,Renewals_HealthScore!I:I,"Renewed"),1),"-") -> -
A4: 2024-Q3 | B4: =IFERROR(ROUND(AVERAGEIFS(Clients_Onboarding!L:L,Clients_Onboarding!P:P,A4,Clients_Onboarding!M:M,"Completed"),1),"-") -> 15 | C4: =IFERROR(ROUND(COUNTIFS(Clients_Onboarding!P:P,A4,Clients_Onboarding!N:N,"Yes")/COUNTIFS(Clients_Onboarding!P:P,A4,Clients_Onboarding!M:M,"Completed"),3),"-") -> 0.5 | D4: =IFERROR(ROUND(AVERAGEIFS(Clients_Onboarding!O:O,Clients_Onboarding!P:P,A4),2),"-") -> 3.88 | E4: =COUNTIFS(Renewals_HealthScore!L:L,A4) -> 0 | F4: =COUNTIFS(Renewals_HealthScore!L:L,A4,Renewals_HealthScore!I:I,"Renewed")+COUNTIFS(Renewals_HealthScore!L:L,A4,Renewals_HealthScore!I:I,"Renewed - Upsold") -> 0 | G4: =IFERROR(ROUND(F4/E4,3),"-") -> - | H4: =COUNTIFS(Renewals_HealthScore!L:L,A4,Renewals_HealthScore!I:I,"Churned") -> 0 | I4: =IFERROR(ROUND(AVERAGEIFS(Renewals_HealthScore!H:H,Renewals_HealthScore!L:L,A4,Renewals_HealthScore!I:I,"Churned"),1),"-") -> - | J4: =IFERROR(ROUND(AVERAGEIFS(Renewals_HealthScore!H:H,Renewals_HealthScore!L:L,A4,Renewals_HealthScore!I:I,"Renewed"),1),"-") -> -
A5: 2024-Q4 | B5: =IFERROR(ROUND(AVERAGEIFS(Clients_Onboarding!L:L,Clients_Onboarding!P:P,A5,Clients_Onboarding!M:M,"Completed"),1),"-") -> 17 | C5: =IFERROR(ROUND(COUNTIFS(Clients_Onboarding!P:P,A5,Clients_Onboarding!N:N,"Yes")/COUNTIFS(Clients_Onboarding!P:P,A5,Clients_Onboarding!M:M,"Completed"),3),"-") -> 0.231 | D5: =IFERROR(ROUND(AVERAGEIFS(Clients_Onboarding!O:O,Clients_Onboarding!P:P,A5),2),"-") -> 4.06 | E5: =COUNTIFS(Renewals_HealthScore!L:L,A5) -> 0 | F5: =COUNTIFS(Renewals_HealthScore!L:L,A5,Renewals_HealthScore!I:I,"Renewed")+COUNTIFS(Renewals_HealthScore!L:L,A5,Renewals_HealthScore!I:I,"Renewed - Upsold") -> 0 | G5: =IFERROR(ROUND(F5/E5,3),"-") -> - | H5: =COUNTIFS(Renewals_HealthScore!L:L,A5,Renewals_HealthScore!I:I,"Churned") -> 0 | I5: =IFERROR(ROUND(AVERAGEIFS(Renewals_HealthScore!H:H,Renewals_HealthScore!L:L,A5,Renewals_HealthScore!I:I,"Churned"),1),"-") -> - | J5: =IFERROR(ROUND(AVERAGEIFS(Renewals_HealthScore!H:H,Renewals_HealthScore!L:L,A5,Renewals_HealthScore!I:I,"Renewed"),1),"-") -> -
A6: 2025-Q1 | B6: =IFERROR(ROUND(AVERAGEIFS(Clients_Onboarding!L:L,Clients_Onboarding!P:P,A6,Clients_Onboarding!M:M,"Completed"),1),"-") -> 17.8 | C6: =IFERROR(ROUND(COUNTIFS(Clients_Onboarding!P:P,A6,Clients_Onboarding!N:N,"Yes")/COUNTIFS(Clients_Onboarding!P:P,A6,Clients_Onboarding!M:M,"Completed"),3),"-") -> 0.263 | D6: =IFERROR(ROUND(AVERAGEIFS(Clients_Onboarding!O:O,Clients_Onboarding!P:P,A6),2),"-") -> 3.81 | E6: =COUNTIFS(Renewals_HealthScore!L:L,A6) -> 1 | F6: =COUNTIFS(Renewals_HealthScore!L:L,A6,Renewals_HealthScore!I:I,"Renewed")+COUNTIFS(Renewals_HealthScore!L:L,A6,Renewals_HealthScore!I:I,"Renewed - Upsold") -> 1 | G6: =IFERROR(ROUND(F6/E6,3),"-") -> 1 | H6: =COUNTIFS(Renewals_HealthScore!L:L,A6,Renewals_HealthScore!I:I,"Churned") -> 0 | I6: =IFERROR(ROUND(AVERAGEIFS(Renewals_HealthScore!H:H,Renewals_HealthScore!L:L,A6,Renewals_HealthScore!I:I,"Churned"),1),"-") -> - | J6: =IFERROR(ROUND(AVERAGEIFS(Renewals_HealthScore!H:H,Renewals_HealthScore!L:L,A6,Renewals_HealthScore!I:I,"Renewed"),1),"-") -> 49.6
A7: 2025-Q2 | B7: =IFERROR(ROUND(AVERAGEIFS(Clients_Onboarding!L:L,Clients_Onboarding!P:P,A7,Clients_Onboarding!M:M,"Completed"),1),"-") -> 19 | C7: =IFERROR(ROUND(COUNTIFS(Clients_Onboarding!P:P,A7,Clients_Onboarding!N:N,"Yes")/COUNTIFS(Clients_Onboarding!P:P,A7,Clients_Onboarding!M:M,"Completed"),3),"-") -> 0.185 | D7: =IFERROR(ROUND(AVERAGEIFS(Clients_Onboarding!O:O,Clients_Onboarding!P:P,A7),2),"-") -> 3.95 | E7: =COUNTIFS(Renewals_HealthScore!L:L,A7) -> 9 | F7: =COUNTIFS(Renewals_HealthScore!L:L,A7,Renewals_HealthScore!I:I,"Renewed")+COUNTIFS(Renewals_HealthScore!L:L,A7,Renewals_HealthScore!I:I,"Renewed - Upsold") -> 9 | G7: =IFERROR(ROUND(F7/E7,3),"-") -> 1 | H7: =COUNTIFS(Renewals_HealthScore!L:L,A7,Renewals_HealthScore!I:I,"Churned") -> 0 | I7: =IFERROR(ROUND(AVERAGEIFS(Renewals_HealthScore!H:H,Renewals_HealthScore!L:L,A7,Renewals_HealthScore!I:I,"Churned"),1),"-") -> - | J7: =IFERROR(ROUND(AVERAGEIFS(Renewals_HealthScore!H:H,Renewals_HealthScore!L:L,A7,Renewals_HealthScore!I:I,"Renewed"),1),"-") -> 54.8
A8: 2025-Q3 | B8: =IFERROR(ROUND(AVERAGEIFS(Clients_Onboarding!L:L,Clients_Onboarding!P:P,A8,Clients_Onboarding!M:M,"Completed"),1),"-") -> 22.6 | C8: =IFERROR(ROUND(COUNTIFS(Clients_Onboarding!P:P,A8,Clients_Onboarding!N:N,"Yes")/COUNTIFS(Clients_Onboarding!P:P,A8,Clients_Onboarding!M:M,"Completed"),3),"-") -> 0.053 | D8: =IFERROR(ROUND(AVERAGEIFS(Clients_Onboarding!O:O,Clients_Onboarding!P:P,A8),2),"-") -> 4.02 | E8: =COUNTIFS(Renewals_HealthScore!L:L,A8) -> 12 | F8: =COUNTIFS(Renewals_HealthScore!L:L,A8,Renewals_HealthScore!I:I,"Renewed")+COUNTIFS(Renewals_HealthScore!L:L,A8,Renewals_HealthScore!I:I,"Renewed - Upsold") -> 10 | G8: =IFERROR(ROUND(F8/E8,3),"-") -> 0.833 | H8: =COUNTIFS(Renewals_HealthScore!L:L,A8,Renewals_HealthScore!I:I,"Churned") -> 0 | I8: =IFERROR(ROUND(AVERAGEIFS(Renewals_HealthScore!H:H,Renewals_HealthScore!L:L,A8,Renewals_HealthScore!I:I,"Churned"),1),"-") -> - | J8: =IFERROR(ROUND(AVERAGEIFS(Renewals_HealthScore!H:H,Renewals_HealthScore!L:L,A8,Renewals_HealthScore!I:I,"Renewed"),1),"-") -> 56.8
A9: 2025-Q4 | B9: =IFERROR(ROUND(AVERAGEIFS(Clients_Onboarding!L:L,Clients_Onboarding!P:P,A9,Clients_Onboarding!M:M,"Completed"),1),"-") -> 22.7 | C9: =IFERROR(ROUND(COUNTIFS(Clients_Onboarding!P:P,A9,Clients_Onboarding!N:N,"Yes")/COUNTIFS(Clients_Onboarding!P:P,A9,Clients_Onboarding!M:M,"Completed"),3),"-") -> 0.026 | D9: =IFERROR(ROUND(AVERAGEIFS(Clients_Onboarding!O:O,Clients_Onboarding!P:P,A9),2),"-") -> 3.86 | E9: =COUNTIFS(Renewals_HealthScore!L:L,A9) -> 26 | F9: =COUNTIFS(Renewals_HealthScore!L:L,A9,Renewals_HealthScore!I:I,"Renewed")+COUNTIFS(Renewals_HealthScore!L:L,A9,Renewals_HealthScore!I:I,"Renewed - Upsold") -> 21 | G9: =IFERROR(ROUND(F9/E9,3),"-") -> 0.808 | H9: =COUNTIFS(Renewals_HealthScore!L:L,A9,Renewals_HealthScore!I:I,"Churned") -> 4 | I9: =IFERROR(ROUND(AVERAGEIFS(Renewals_HealthScore!H:H,Renewals_HealthScore!L:L,A9,Renewals_HealthScore!I:I,"Churned"),1),"-") -> 52.2 | J9: =IFERROR(ROUND(AVERAGEIFS(Renewals_HealthScore!H:H,Renewals_HealthScore!L:L,A9,Renewals_HealthScore!I:I,"Renewed"),1),"-") -> 54
A10: 2026-Q1 | B10: =IFERROR(ROUND(AVERAGEIFS(Clients_Onboarding!L:L,Clients_Onboarding!P:P,A10,Clients_Onboarding!M:M,"Completed"),1),"-") -> 25.1 | C10: =IFERROR(ROUND(COUNTIFS(Clients_Onboarding!P:P,A10,Clients_Onboarding!N:N,"Yes")/COUNTIFS(Clients_Onboarding!P:P,A10,Clients_Onboarding!M:M,"Completed"),3),"-") -> 0 | D10: =IFERROR(ROUND(AVERAGEIFS(Clients_Onboarding!O:O,Clients_Onboarding!P:P,A10),2),"-") -> 3.81 | E10: =COUNTIFS(Renewals_HealthScore!L:L,A10) -> 19 | F10: =COUNTIFS(Renewals_HealthScore!L:L,A10,Renewals_HealthScore!I:I,"Renewed")+COUNTIFS(Renewals_HealthScore!L:L,A10,Renewals_HealthScore!I:I,"Renewed - Upsold") -> 14 | G10: =IFERROR(ROUND(F10/E10,3),"-") -> 0.737 | H10: =COUNTIFS(Renewals_HealthScore!L:L,A10,Renewals_HealthScore!I:I,"Churned") -> 4 | I10: =IFERROR(ROUND(AVERAGEIFS(Renewals_HealthScore!H:H,Renewals_HealthScore!L:L,A10,Renewals_HealthScore!I:I,"Churned"),1),"-") -> 58.6 | J10: =IFERROR(ROUND(AVERAGEIFS(Renewals_HealthScore!H:H,Renewals_HealthScore!L:L,A10,Renewals_HealthScore!I:I,"Renewed"),1),"-") -> 52
A11: 2026-Q2 | B11: =IFERROR(ROUND(AVERAGEIFS(Clients_Onboarding!L:L,Clients_Onboarding!P:P,A11,Clients_Onboarding!M:M,"Completed"),1),"-") -> 26.5 | C11: =IFERROR(ROUND(COUNTIFS(Clients_Onboarding!P:P,A11,Clients_Onboarding!N:N,"Yes")/COUNTIFS(Clients_Onboarding!P:P,A11,Clients_Onboarding!M:M,"Completed"),3),"-") -> 0 | D11: =IFERROR(ROUND(AVERAGEIFS(Clients_Onboarding!O:O,Clients_Onboarding!P:P,A11),2),"-") -> 3.62 | E11: =COUNTIFS(Renewals_HealthScore!L:L,A11) -> 27 | F11: =COUNTIFS(Renewals_HealthScore!L:L,A11,Renewals_HealthScore!I:I,"Renewed")+COUNTIFS(Renewals_HealthScore!L:L,A11,Renewals_HealthScore!I:I,"Renewed - Upsold") -> 20 | G11: =IFERROR(ROUND(F11/E11,3),"-") -> 0.741 | H11: =COUNTIFS(Renewals_HealthScore!L:L,A11,Renewals_HealthScore!I:I,"Churned") -> 4 | I11: =IFERROR(ROUND(AVERAGEIFS(Renewals_HealthScore!H:H,Renewals_HealthScore!L:L,A11,Renewals_HealthScore!I:I,"Churned"),1),"-") -> 53.4 | J11: =IFERROR(ROUND(AVERAGEIFS(Renewals_HealthScore!H:H,Renewals_HealthScore!L:L,A11,Renewals_HealthScore!I:I,"Renewed"),1),"-") -> 55.5

Sheet Data_Dictionary
A1: Sheet | B1: Column | C1: Description
A2: Clients_Onboarding | B2: client_id | C2: Unique client identifier
A3: Clients_Onboarding | B3: company_name | C3: Fictional client company name
A4: Clients_Onboarding | B4: industry | C4: Client's industry vertical
A5: Clients_Onboarding | B5: region | C5: City/region of the client (India)
A6: Clients_Onboarding | B6: company_size | C6: Employee headcount band
A7: Clients_Onboarding | B7: plan_type | C7: Subscription tier: Starter / Growth / Enterprise
A8: Clients_Onboarding | B8: sales_rep | C8: Sales rep who closed the deal
A9: Clients_Onboarding | B9: csm_assigned | C9: Customer Success Manager assigned for onboarding
A10: Clients_Onboarding | B10: contract_signed_date | C10: Date the client signed the contract
A11: Clients_Onboarding | B11: onboarding_start_date | C11: Date onboarding officially began
A12: Clients_Onboarding | B12: onboarding_complete_date | C12: Date onboarding was marked complete (blank if dropped/in progress)
... A29: Renewals_HealthScore | B29: renewal_quarter | C29: Quarter the renewal decision fell in
